Workbook

Sheet Instrucoes
A1: Rubrica de avaliacao — TCC LLMs x Complexidade Progressiva
A2: Preencha as celulas amarelas na aba 'Avaliacao' apos revisar cada um dos 30 arquivos em outputs/.
A4: Coluna | B4: Como preencher
A5: Rodou sem erro? (S/N) | B5: Extraia o codigo do .md, rode de verdade (idealmente em container/ambiente isolado). 'S' se rodou de primeira ou com erro trivial de digitacao; 'N' se precisou de correcao estrutural.
A6: Nº de correcoes manuais | B6: Quantas mudancas voce precisou fazer no codigo ate ele funcionar. 0 = rodou de primeira.
A7: Completude (0-5) | B7: 0 = nao atende nada do prompt; 5 = atende 100% dos requisitos pedidos no nivel.
A8: Qualidade estatica (warnings) | B8: Rode um linter (ex: eslint) no codigo gerado e anote o numero de warnings/erros.
A9: Boas praticas (1-5) | B9: Avaliacao qualitativa: separacao de responsabilidades, tratamento de erros, nomes claros, comentarios uteis.
A10: Seguranca (1-5) | B10: Preencha SO a partir do nivel 4 (autenticacao). Considere: hash de senha, protecao contra SQL injection, validacao de entrada, exposicao de dados sensiveis em respostas de erro.
A11: Observacoes | B11: Qualquer coisa notavel: o modelo pulou um requisito, adicionou algo nao pedido, decisao de design questionavel, etc.
A13: Legenda de cores
A14: Preencher (amarelo)
A15: Ja preenchido / calculado (cinza claro)
A16: Linha de exemplo (verde)
A18: Preenchido com dados reais (testado)
A19: Truncado / bloqueado - precisa rerodar ou testar localmente
A22: Status final: 30/30 combinacoes testadas e preenchidas com dados reais.

Sheet Avaliacao
A1: Avaliacao — 30 combinacoes (5 niveis x 3 provedores x 2 tentativas)
A2: Nivel | B2: Nome do nivel | C2: Provedor | D2: Modelo exato | E2: Tentativa | F2: Tamanho (chars) | G2: Rodou sem erro? (S/N) | H2: Nº correcoes manuais | I2: Completude (0-5) | J2: Qualidade estatica (warnings) | K2: Boas praticas (1-5) | L2: Seguranca (1-5) | M2: Observacoes | N2: Arquivo
A3: 0 | B3: Persistencia simples | C3: claude | D3: claude-sonnet-5 | E3: 1 | F3: 6949 | G3: S | H3: 0 | I3: 5 | J3: 0 | K3: 5 | M3: Rodou de primeira (CLI e interativo). Escaping CSV RFC4180 correto; append seguro. | N3: outputs/nivel-0-persistencia-simples/claude/tentativa-1.md
A4: 0 | B4: Persistencia simples | C4: claude | D4: claude-sonnet-5 | E4: 2 | F4: 7308 | G4: S | H4: 0 | I4: 5 | J4: 0 | K4: 5 | M4: Mesma robustez da tentativa 1; pequenas variações de nomenclatura interna. | N4: outputs/nivel-0-persistencia-simples/claude/tentativa-2.md
A5: 0 | B5: Persistencia simples | C5: gpt | D5: gpt-5.6 | E5: 1 | F5: 3794 | G5: S | H5: 0 | I5: 5 | J5: 0 | K5: 5 | M5: Usa fs/promises + readline/promises; detecta arquivo vazio antes de escrever cabecalho. | N5: outputs/nivel-0-persistencia-simples/gpt/tentativa-1.md
A6: 0 | B6: Persistencia simples | C6: gpt | D6: gpt-5.6 | E6: 2 | F6: 5011 | G6: S | H6: 0 | I6: 5 | J6: 0 | K6: 5 | M6: Mais defensivo: detecta ausencia de TTY (evita travar esperando input) e checa byte final do arquivo. | N6: outputs/nivel-0-persistencia-simples/gpt/tentativa-2.md
A7: 0 | B7: Persistencia simples | C7: gemini | D7: gemini-pro-latest | E7: 1 | F7: 3887 | G7: S | H7: 0 | I7: 4 | J7: 0 | K7: 4 | M7: So aceita nome via argv, sem fallback interativo (exit(1) se omitido). | N7: outputs/nivel-0-persistencia-simples/gemini/tentativa-1.md
A8: 0 | B8: Persistencia simples | C8: gemini | D8: gemini-pro-latest | E8: 2 | F8: 4038 | G8: S | H8: 0 | I8: 3 | J8: 0 | K8: 3 | M8: IGNORA argv por completo - so funciona em modo interativo. Inconsistente com a propria tentativa 1. | N8: outputs/nivel-0-persistencia-simples/gemini/tentativa-2.md
A9: 1 | B9: CRUD com persistencia em banco | C9: claude | D9: claude-sonnet-5 | E9: 1 | F9: 2976 | G9: S | H9: 0 | I9: 5 | J9: 0 | K9: 5 | M9: RERODADO com harness corrigido - nao truncou mais (end_turn, 7421 tokens). CRUD 100% funcional: add/list/update/remove, duplicidade rejeitada corretamente. Arquitetura em camadas (db/validators/userService/cli). | N9: outputs/nivel-1-crud-com-persistencia-em-banco/claude/tentativa-1.md
A10: 1 | B10: CRUD com persistencia em banco | C10: claude | D10: claude-sonnet-5 | E10: 2 | F10: 2298 | G10: S | H10: 0 | I10: 5 | J10: 0 | K10: 5 | M10: RERODADO com harness corrigido - nao truncou mais (end_turn, 8660 tokens). CRUD 100% funcional. Bonus: oferece menu interativo alem de argv (unico entre os projetos testados a suportar os dois modos de verdade). | N10: outputs/nivel-1-crud-com-persistencia-em-banco/claude/tentativa-2.md
A11: 1 | B11: CRUD com persistencia em banco | C11: gpt | D11: gpt-5.6 | E11: 1 | F11: 20478 | G11: S | H11: 0 | I11: 5 | J11: 0 | K11: 5 | M11: 100% de primeira: cadastro, rejeicao de duplicidade com mensagem amigavel, listagem em tabela, atualizacao e remocao - todos testados com sucesso. | N11: outputs/nivel-1-crud-com-persistencia-em-banco/gpt/tentativa-1.md
A12: 1 | B12: CRUD com persistencia em banco | C12: gpt | D12: gpt-5.6 | E12: 2 | F12: 19878 | G12: S | H12: 0 | I12: 5 | J12: 0 | K12: 5 | M12: 100% de primeira, incluindo duplicidade case-insensitive (JOAO@ vs joao@) via COLLATE NOCASE. | N12: outputs/nivel-1-crud-com-persistencia-em-banco/gpt/tentativa-2.md
A13: 1 | B13: CRUD com persistencia em banco | C13: gemini | D13: gemini-pro-latest | E13: 1 | F13: 7882 | G13: S | H13: 0 | I13: 5 | J13: 0 | K13: 4 | M13: TESTADO PELO USUARIO na propria maquina (better-sqlite3^9.4.3 nao instala no sandbox de teste, mas instala normalmente localmente apos ajuste de versao para ^12.2.0). Menu interativo completo: cadastro, listagem em tabela, duplicidade de email corretamente rejeitada. | N13: outputs/nivel-1-crud-com-persistencia-em-banco/gemini/tentativa-1.md
A14: 1 | B14: CRUD com persistencia em banco | C14: gemini | D14: gemini-pro-latest | E14: 2 | F14: 6325 | G14: S | H14: 0 | I14: 5 | J14: 0 | K14: 4 | M14: TESTADO PELO USUARIO na propria maquina (mesma ressalva de instalacao da t1). CLI via argv (add/list), duplicidade de email corretamente rejeitada. | N14: outputs/nivel-1-crud-com-persistencia-em-banco/gemini/tentativa-2.md
... A26: 3 | B26: Sistema web full-stack | C26: gemini | D26: gemini-pro-latest | E26: 2 | F26: 11072 | G26: S | H26: 0 | I26: 5 | J26: 0 | K26: 4 | M26: CRUD completo funcional, identico em estrutura a t1. Diferenca: mensagem de erro amigavel na duplicidade ('Email pode ja existir') em vez de vazar o erro do SQLite - mais cuidadoso que a t1 nesse ponto especifico. | N26: outputs/nivel-3-sistema-web-full-stack/gemini/tentativa-2.md
A27: 4 | B27: Seguranca (autenticacao e autorizacao) | C27: claude | D27: claude-sonnet-5 | E27: 1 | F27: 24062 | G27: S | H27: 0 | I27: 4 | J27: 6 | K27: 4 | L27: 4 | M27: SEGURANCA - testado de ponta a ponta. Interpretacao de dados DIFERENTE dos outros dois modelos: separa 'users' (login) de 'records' (o que e de fato cadastrado, com titulo+descricao e dono/owner via JOIN) - leitura valida do prompt, ja que o nivel nao especificava os campos. Hash com scrypt nativo do Node + timingSafeEqual (mesmo nivel do GPT). JWT_SECRET vem de env var com fallback CLARAMENTE rotulado 'dev-secret-nao-use-em-producao' (bem melhor que o secret hardcoded do Gemini, que nao alertava nada). Cookie: httpOnly + sameSite=lax (comentado explicitamente como mitigacao de CSRF) + secure condicional a NODE_ENV=production. Sem admin padrao: usa endpoint publico /register para autocadastro, sem senha fraca pre-definida. NAO tem token CSRF dedicado (diferente do GPT) - depende so do sameSite=lax, que e uma protecao real mas mais fraca que double-submit token. | N27: outputs/nivel-4-seguranca-autenticacao-e-autorizacao/claude/tentativa-1.md
A28: 4 | B28: Seguranca (autenticacao e autorizacao) | C28: claude | D28: claude-sonnet-5 | E28: 2 | F28: 23648 | G28: S | H28: 0 | I28: 4 | J28: 7 | K28: 4 | L28: 4 | M28: SEGURANCA - mesmo padrao de qualidade da t1 (sameSite=lax comentado, secret com fallback rotulado como dev, endpoint /register publico, sem admin padrao fraco). Diferenca: usa bcryptjs (hash $2a$10$..., salgado corretamente) em vez de scrypt nativo - escolha tambem valida, mas sem a mitigacao extra de timing attack via timingSafeEqual que o bcrypt ja resolve internamente por design. Testado ponta a ponta: listagem publica, bloqueio sem sessao (401), registro+login+criacao autenticada funcionando. | N28: outputs/nivel-4-seguranca-autenticacao-e-autorizacao/claude/tentativa-2.md
A29: 4 | B29: Seguranca (autenticacao e autorizacao) | C29: gpt | D29: gpt-5.6 | E29: 1 | F29: 43514 | G29: S | H29: 0 | I29: 5 | J29: 4 | K29: 5 | L29: 5 | M29: SEGURANCA - a implementacao mais rigorosa dos 3 modelos, testada de ponta a ponta. Hash com scrypt (parametros explicitos N=16384/r=8/p=1) + comparacao em tempo constante (timingSafeEqual) - protege contra timing attack, algo que nem o Gemini fez. Sessao armazenada no servidor (token aleatorio, nao JWT) - revogavel, sem secret no codigo. Cookie com sameSite=lax + secure condicional + httpOnly. CSRF REAL: token dedicado por sessao, exigido via header x-csrf-token, comparado em tempo constante - testei o ataque simulado (cookie presente, sem header) e foi bloqueado (403); fluxo legitimo com token correto funcionou (201). NAO cria admin padrao com senha fraca - exige script separado (create-admin) com senha via variavel de ambiente, evitando expor a senha no historico do shell. | N29: outputs/nivel-4-seguranca-autenticacao-e-autorizacao/gpt/tentativa-1.md
A30: 4 | B30: Seguranca (autenticacao e autorizacao) | C30: gpt | D30: gpt-5.6 | E30: 2 | F30: 47395 | G30: S | H30: 0 | I30: 5 | J30: 1 | K30: 5 | L30: 5 | M30: SEGURANCA - mesma robustez da t1, com um detalhe a mais: sameSite='strict' (mais restritivo que 'lax' da t1), e executa o scrypt mesmo quando o usuario nao existe no login, de proposito, para que tentativas com usuario invalido e senha errada demorem o mesmo tempo - mitigacao de timing attack no proprio endpoint de login, raro de ver implementado. CSRF testado e confirmado: ataque sem token bloqueado (403), fluxo legitimo passou pelas camadas de auth+CSRF corretamente. | N30: outputs/nivel-4-seguranca-autenticacao-e-autorizacao/gpt/tentativa-2.md
A31: 4 | B31: Seguranca (autenticacao e autorizacao) | C31: gemini | D31: gemini-pro-latest | E31: 1 | F31: 11590 | G31: S | H31: 0 | I31: 5 | J31: 5 | K31: 3 | L31: 3 | M31: SEGURANCA - testado de ponta a ponta: listagem publica (200) e /add e /delete corretamente bloqueados sem sessao (302), liberados com sessao valida. Senha com hash bcrypt real e salgado ($2b$10$..., unico por usuario) - nao ha senha em texto puro no banco. PORTAS: ignora env PORT (hardcoded 3000, mesmo padrao dos outros niveis do Gemini). FALHAS DE SEGURANCA REAIS: (1) JWT_SECRET hardcoded no codigo-fonte; (2) usuario admin padrao com senha fraca 'admin123' criado automaticamente e logado no console; (3) cookie de sessao SEM SameSite nem Secure explicitos - a app comenta que usa POST em vez de GET para 'evitar CSRF simples', o que e um equivoco: POST sozinho nao previne CSRF; sem SameSite explicito a protecao depende so do default do navegador, nao de decisao de design. | N31: outputs/nivel-4-seguranca-autenticacao-e-autorizacao/gemini/tentativa-1.md
A32: 4 | B32: Seguranca (autenticacao e autorizacao) | C32: gemini | D32: gemini-pro-latest | E32: 2 | F32: 14613 | G32: S | H32: 0 | I32: 5 | J32: 2 | K32: 3 | L32: 3 | M32: SEGURANCA - testado de ponta a ponta. Mesmo JWT_SECRET hardcoded da t1 ('super_secret_key_123', literalmente identico - sugere que e um valor 'padrao' do modelo, nao aleatorio) e mesmo admin auto-criado com senha fraca (admin/admin123). DIFERENCA ARQUITETURAL relevante: em vez de cookie httpOnly (usado na t1), esta tentativa guarda o JWT em localStorage no frontend e manda via header 'Authorization: Bearer'. Troca um risco por outro: elimina a exposicao a CSRF que a t1 tinha (Bearer nao e enviado automaticamente cross-site como cookie), mas introduce exposicao a roubo de token via XSS, ja que localStorage e acessivel por qualquer JS da pagina (diferente de cookie httpOnly, que o JS nao consegue ler). Testado: listagem publica (200), criacao sem token bloqueada (401), hash bcrypt salgado confirmado no banco. | N32: outputs/nivel-4-seguranca-autenticacao-e-autorizacao/gemini/tentativa-2.md
A33: 0 | B33: Persistencia simples | C33: groq | D33: openai/gpt-oss-120b | E33: 1 | F33: 6030 | G33: S | H33: 0 | I33: 5 | J33: 0 | K33: 5 | L33: N/A | M33: Confirmado em teste local pelo autor (28/08/2026): duas execucoes consecutivas, users.csv com duas linhas, sem sobrescrever a anterior. Nao testavel no sandbox automatizado por exigir terminal real (prompt-sync) - mesma categoria do Gemini nivel 1.
A34: 0 | B34: Persistencia simples | C34: groq | D34: openai/gpt-oss-120b | E34: 2 | F34: 5531 | G34: S | H34: 0 | I34: 5 | J34: 0 | K34: 5 | L34: N/A | M34: Via argumento de linha de comando (nao interativo). Testado: duas execucoes, CSV com 2 linhas, sem sobrescrever.
A35: 1 | B35: CRUD com persistencia em banco | C35: groq | D35: openai/gpt-oss-120b | E35: 1 | F35: 13346 | G35: S | H35: 0 | I35: 5 | J35: 0 | K35: 5 | L35: N/A | M35: CRUD completo via commander (add/list/update/delete), com confirmacao y/n na remocao. Testado: cadastro, duplicidade de e-mail rejeitada, atualizacao, remocao - tudo funcional.
A36: 1 | B36: CRUD com persistencia em banco | C36: groq | D36: openai/gpt-oss-120b | E36: 2 | F36: 13965 | G36: S | H36: 2 | I36: 5 | J36: 0 | K36: 4 | L36: N/A | M36: Confirmado em teste local pelo autor (28/08/2026), apos correcao de 2 dependencias (better-sqlite3 e inquirer, ver Seccao metodologica): cadastro, listagem e bloqueio de e-mail duplicado (mensagem amigavel, sem prosseguir) - tudo funcional. Nao testavel no sandbox automatizado por exigir terminal real (inquirer) - mesma categoria do Gemini nivel 1.
A37: 2 | B37: API REST | C37: groq | D37: openai/gpt-oss-120b | E37: 1 | F37: 11994 | G37: S | H37: 1 | I37: 5 | J37: 2 | K37: 5 | L37: N/A | M37: 1 correcao manual: package.json continha uma linha de comentario invalida ('// package.json') dentro do JSON, quebrando o parsing - removida. Apos a correcao: CRUD completo via /users, 409 correto para e-mail duplicado.
A38: 2 | B38: API REST | C38: groq | D38: openai/gpt-oss-120b | E38: 2 | F38: 11651 | G38: S | H38: 1 | I38: 5 | J38: 3 | K38: 4 | L38: N/A | M38: 1 correcao manual: codigo importava o pacote 'sqlite' (wrapper de promises), mas so 'sqlite3' estava declarado no package.json - adicionado. CRUD funcional, mas retorna 400 (nao 409) para e-mail duplicado - inconsistente com a tentativa 1 do mesmo modelo.
A39: 3 | B39: Sistema web full-stack | C39: groq | D39: openai/gpt-oss-120b | E39: 1 | F39: 14221 | G39: S | H39: 0 | I39: 5 | J39: 1 | K39: 5 | L39: N/A | M39: Rotas em /api/users (nao /users, como a descricao inicial sugeria). Campo 'age' em vez de 'birthdate' - interpretacao valida, pois o nivel nao especifica campos. CRUD completo testado, 409 correto; DELETE retorna 200 em vez de 204 (estilo, nao erro).
A40: 3 | B40: Sistema web full-stack | C40: groq | D40: openai/gpt-oss-120b | E40: 2 | F40: 14567 | G40: S | H40: 0 | I40: 5 | J40: 1 | K40: 4 | L40: N/A | M40: CRUD completo funcional, 409 correto, DELETE 204. Boas praticas com ressalva: um stack trace bruto do SQLite (constraint de e-mail duplicado) e impresso no console do servidor mesmo a API respondendo corretamente ao cliente - vazamento de log, nao de seguranca.
A41: 4 | B41: Seguranca (autenticacao e autorizacao) | C41: groq | D41: openai/gpt-oss-120b | E41: 1 | F41: 11772 | G41: S | H41: 2 | I41: 5 | J41: 0 | L41: 4 | M41: 2 correcoes manuais: dependencia 'dotenv' usada no codigo mas ausente do package.json (adicionada); e o arquivo db/schema.sql nao foi extraido automaticamente (cabecalho com nome de arquivo entre parenteses no meio da frase, fora do padrao de extracao - criado manualmente com o conteudo exato do .md original, e o extrator foi atualizado para esse padrao). Seguranca: bcrypt correto, autenticacao via Bearer token (token nao enviado automaticamente pelo navegador em requisicoes cross-site, logo sem exposicao a CSRF por arquitetura), sem admin padrao (autocadastro publico). Segredo JWT com fallback rotulado (nao hardcoded puro).
A42: 4 | B42: Seguranca (autenticacao e autorizacao) | C42: groq | D42: openai/gpt-oss-120b | E42: 2 | F42: 14388 | G42: S | H42: 0 | I42: 5 | J42: 1 | K42: 3 | L42: 3 | M42: Arquitetura diferente da tentativa 1: usa cookie de sessao em vez de Bearer token. bcrypt correto (confirmado no banco), bloqueio sem token funcional. Porem cookie SEM atributo SameSite (confirmado via header Set-Cookie bruto) - mesma lacuna de CSRF real encontrada no Gemini nivel 4. Segredo JWT hardcoded com fallback ('supersecretkey'). Inconsistencia arquitetural relevante entre as duas tentativas do mesmo modelo neste nivel.
A43: 0 | B43: Persistencia simples | C43: claude | D43: claude-sonnet-5 | E43: 3 | F43: 16348 | G43: S | H43: 0 | I43: 5 | J43: 0 | K43: 5 | L43: N/A | M43: Interativo (readline) e via argumento; ambos testados com sucesso. CSV com cabecalho, escapamento RFC 4180 completo.
A44: 0 | B44: Persistencia simples | C44: gemini | D44: gemini-3.1-pro-preview | E44: 3 | F44: 3421 | G44: S | H44: 0 | I44: 5 | J44: 0 | K44: 5 | L44: N/A | M44: Via argumento de linha de comando. Testado: duas execucoes, CSV com 2 linhas e cabecalho, sem sobrescrever.
A45: 0 | B45: Persistencia simples | C45: gpt | D45: gpt-5.6 | E45: 3 | F45: 3843 | G45: S | H45: 0 | I45: 5 | J45: 0 | K45: 5 | L45: N/A | M45: Interativo e via argumento. Testado: duas execucoes, CSV com cabecalho, sem sobrescrever.
A46: 0 | B46: Persistencia simples | C46: groq | D46: openai/gpt-oss-120b | E46: 3 | F46: 6146 | G46: S | H46: 0 | I46: 5 | J46: 0 | K46: 5 | L46: N/A | M46: Interativo e via argumento. Testado: duas execucoes, CSV sem cabecalho mas sem sobrescrever.
A47: 1 | B47: CRUD com persistencia em banco | C47: claude | D47: claude-sonnet-5 | E47: 3 | F47: 16263 | G47: S | H47: 0 | I47: 5 | J47: 0 | K47: 5 | L47: N/A | M47: CLI com parsing manual de argumentos (--name/--email/--dob). CRUD completo testado: cadastro, duplicidade de e-mail rejeitada, atualizacao, remocao.
A48: 1 | B48: CRUD com persistencia em banco | C48: gemini | D48: gemini-3.1-pro-preview | E48: 3 | F48: 8189 | G48: S | H48: 0 | I48: 5 | J48: 0 | K48: 4 | L48: N/A | M48: Menu interativo via readline; testavel neste sandbox apenas com delay artificial entre respostas simuladas (limitacao de teste, nao do codigo). Cadastro e listagem confirmados.
A49: 1 | B49: CRUD com persistencia em banco | C49: gpt | D49: gpt-5.6 | E49: 3 | F49: 23557 | G49: S | H49: 0 | I49: 5 | J49: 0 | K49: 5 | L49: N/A | M49: CLI com aliases em portugues/ingles. CRUD completo testado, incluindo confirmacao de seguranca (--sim) exigida para remocao - boa pratica, nao bug.
A50: 1 | B50: CRUD com persistencia em banco | C50: groq | D50: openai/gpt-oss-120b | E50: 3 | F50: 13266 | G50: S | H50: 2 | I50: 5 | J50: 0 | K50: 4 | L50: N/A | M50: 2 correcoes manuais: better-sqlite3^9.4.3 sem binario pre-compilado (subido para ^12.2.0); chalk^5.3.0 e ESM-only, incompativel com require() do codigo (rebaixado para ^4.1.2). Apos corrigir, CRUD completo funcional com duplicidade rejeitada.
A51: 2 | B51: API REST | C51: claude | D51: claude-sonnet-5 | E51: 3 | F51: 19857 | G51: S | H51: 0 | I51: 5 | J51: 1 | K51: 5 | L51: N/A | M51: API REST completa testada via HTTP real: criar, listar, 409 em duplicidade.
...

Sheet Resumo por Provedor
A1: Resumo agregado por provedor
A2: Calculado automaticamente a partir da aba 'Avaliacao' - preencha aquela aba primeiro.
A4: Provedor | B4: Taxa de sucesso (%) | C4: Media correcoes manuais | D4: Completude media | E4: Qualidade estatica media (warnings) | F4: Boas praticas media | G4: Seguranca media (nivel 4)
A5: claude | B5: =IFERROR(COUNTIFS(Avaliacao!C3:C62,A5,Avaliacao!G3:G62,"S")/COUNTIFS(Avaliacao!C3:C62,A5,Avaliacao!G3:G62,"<>")*100,"") -> 100 | C5: =IFERROR(AVERAGEIFS(Avaliacao!H3:H62,Avaliacao!C3:C62,A5),"") -> 0 | D5: =IFERROR(AVERAGEIFS(Avaliacao!I3:I62,Avaliacao!C3:C62,A5),"") -> 4.8666667 | E5: =IFERROR(AVERAGEIFS(Avaliacao!J3:J62,Avaliacao!C3:C62,A5),"") -> 1.2 | F5: =IFERROR(AVERAGEIFS(Avaliacao!K3:K62,Avaliacao!C3:C62,A5),"") -> 4.8666667 | G5: =IFERROR(AVERAGEIFS(Avaliacao!L3:L62,Avaliacao!C3:C62,A5,Avaliacao!A3:A62,4),"") -> 4
A6: gpt | B6: =IFERROR(COUNTIFS(Avaliacao!C3:C62,A6,Avaliacao!G3:G62,"S")/COUNTIFS(Avaliacao!C3:C62,A6,Avaliacao!G3:G62,"<>")*100,"") -> 100 | C6: =IFERROR(AVERAGEIFS(Avaliacao!H3:H62,Avaliacao!C3:C62,A6),"") -> 0 | D6: =IFERROR(AVERAGEIFS(Avaliacao!I3:I62,Avaliacao!C3:C62,A6),"") -> 5 | E6: =IFERROR(AVERAGEIFS(Avaliacao!J3:J62,Avaliacao!C3:C62,A6),"") -> 0.86666667 | F6: =IFERROR(AVERAGEIFS(Avaliacao!K3:K62,Avaliacao!C3:C62,A6),"") -> 4.9333333 | G6: =IFERROR(AVERAGEIFS(Avaliacao!L3:L62,Avaliacao!C3:C62,A6,Avaliacao!A3:A62,4),"") -> 5
A7: gemini | B7: =IFERROR(COUNTIFS(Avaliacao!C3:C62,A7,Avaliacao!G3:G62,"S")/COUNTIFS(Avaliacao!C3:C62,A7,Avaliacao!G3:G62,"<>")*100,"") -> 100 | C7: =IFERROR(AVERAGEIFS(Avaliacao!H3:H62,Avaliacao!C3:C62,A7),"") -> 0 | D7: =IFERROR(AVERAGEIFS(Avaliacao!I3:I62,Avaliacao!C3:C62,A7),"") -> 4.6 | E7: =IFERROR(AVERAGEIFS(Avaliacao!J3:J62,Avaliacao!C3:C62,A7),"") -> 0.73333333 | F7: =IFERROR(AVERAGEIFS(Avaliacao!K3:K62,Avaliacao!C3:C62,A7),"") -> 3.6 | G7: =IFERROR(AVERAGEIFS(Avaliacao!L3:L62,Avaliacao!C3:C62,A7,Avaliacao!A3:A62,4),"") -> 2.6666667
A8: groq | B8: =IFERROR(COUNTIFS(Avaliacao!C3:C62,A8,Avaliacao!G3:G62,"S")/COUNTIFS(Avaliacao!C3:C62,A8,Avaliacao!G3:G62,"<>")*100,"") -> 100 | C8: =IFERROR(AVERAGEIFS(Avaliacao!H3:H62,Avaliacao!C3:C62,A8),"") -> 0.73333333 | D8: =IFERROR(AVERAGEIFS(Avaliacao!I3:I62,Avaliacao!C3:C62,A8),"") -> 5 | E8: =IFERROR(AVERAGEIFS(Avaliacao!J3:J62,Avaliacao!C3:C62,A8),"") -> 0.53333333 | F8: =IFERROR(AVERAGEIFS(Avaliacao!K3:K62,Avaliacao!C3:C62,A8),"") -> 4.3571429 | G8: =IFERROR(AVERAGEIFS(Avaliacao!L3:L62,Avaliacao!C3:C62,A8,Avaliacao!A3:A62,4),"") -> 3.6666667
